Workbook

Sheet MDB
A1: Employee ID | B1: Process ID | C1: Login ID | D1: Employee Name | E1: Gender | F1: SSC Reg Num. | G1: Designation | H1: Functional Designation/Job Role | I1: Department | J1: Process Segment (LOB) | K1: Process | L1: Employment Type | M1: Sup 1 | N1: Sup 2 | O1: HoD | P1: Training Batch | Q1: DOT | R1: DOJ | S1: Contractual Transfer DOJ | T1: Permanent Transfer DOJ | U1: New Role DOJ | V1: Official Contact | W1: Email | X1: Contact# | Y1: Alt. Cont# | Z1: Emergency Contact Person | AA1: Emergency Number | AB1: Rel. with Employee | AC1: Blood Group | AD1: DOB | AE1: Age | AF1: Religion | AG1: NID# | AH1: Passport# | AI1: Academic Qualification | AJ1: Education Pursuing | AK1: Passing Year | AL1: Institution | AM1: Father's Name | AN1: Mother's Name | AO1: Present Address | AP1: Permanent Address | AQ1: Present Pick Location | AR1: Marital Status | AS1: Spouse Name | AT1: Spouse DOB | AU1: Child-1 Name | AV1: Child-1 DOB | AW1: Child-2 Name | AX1: Child-2 DOB | AY1: Child-3 Name | AZ1: Child-3 DOB | BA1: Status | BB1: Rate 1 | BC1: Rate 2 | BD1: Rate 3 | BE1: Shift | BF1: Previous ID | BG1: Previous Process | BH1: MDB Update | BI1: Personal note BKAsh | BJ1: Official email ID | BK1: Bkash Number | BL1: October Bkash
A2: 171160 | C2: mmaigenex038 | D2: Farzana Akter | E2: Female | F2: 783543 | G2: CSO | H2: Content Moderator | I2: Operations | J2: Content Moderation and Data Annotation | K2: TEMU | L2: Fixed | M2: Halima akter | N2: Asif Iqbal | O2: Ashraful Haq | P2: 2 | Q2: 45029 | R2: 45042 | W2: farjanaraha234@gmail.com | X2: 1817647164 | Z2: Md Abdur Rahim | AA2: 1999087365 | AB2: Husband | AC2: O+ | AD2: 34800 | AE2: =((TODAY())-AD2)/365 -> 29.854795 | AF2: Islam | AG2: 6854249239 | AH2: N/A | AI2: Master's | AJ2: N/A | AK2: N/A | AL2: National university | AM2: Md.Saifuddin | AN2: Jinnat Ara Nargis | AO2: Area : Kha para masjid road, Thana : Khilkhet,Dist : Dhaka | AP2: Vill : Ali Raja Munsi bari,Maddham Chandpur,Lemua,Thana : Feni sadar,Dist : Feni | AQ2: Khilkhet | AR2: Married | BA2: Active | BB2: 10800 | BC2: 2700 | BD2: 0 | BE2: Morning | BF2: 161563 | BG2: Netstar | BH2: Done | BJ2: farzana.akter2@genex.com.bd
A3: 171033 | C3: MahbubaAkterPrema | D3: Mahbuba Akter Prema | E3: Female | F3: 1410954595 | G3: CSO | H3: Content Moderator | I3: Operations | J3: English Customer Service Audio Transcription | K3: TEMU | L3: Fixed | M3: Nazimuddoula Leon | N3: Asif Iqbal | O3: Ashraful Haq | P3: 3 | Q3: 45037 | R3: 45044 | W3: mahhubaprema824@gmail.com | X3: 1954838818 | Z3: Mohammad Ali | AA3: 1913177862 | AB3: Father | AC3: AB+ | AD3: 36632 | AE3: =((TODAY())-AD3)/365 -> 24.835616 | AF3: Islam | AG3: 7364948062 | AH3: AE9139958 | AI3: H.S.C | AJ3: Honour's Running | AK3: 2025 | AL3: Uttara Town College | AM3: Mohammad Ali | AN3: Masuda Begum | AO3: Area : 2210/1 Shahertek,Mazar Road,Thana : Uttarkhan,Dist : Dhaka-1230 | AP3: Area : 2210/1 Shahertek,Mazar Road,Thana : Uttarkhan,Dist : Dhaka-1230 | AQ3: Uttarkhan | AR3: Unmarried | BA3: Active | BB3: 10800 | BC3: 2700 | BD3: 0 | BE3: Morning | BF3: 160673 | BG3: Netstar | BH3: Done | BJ3: mahbuba.prema@genex.com.bd
A4: 171036 | C4: mmaigenex041 | D4: Md. Rakibul Hasan | E4: Male | F4: 1410849604 | G4: CSO | H4: Content Moderator | I4: Operations | J4: Content Moderation and Data Annotation | K4: TEMU | L4: Fixed | M4: Mizanur Rahman | N4: Asif Iqbal | O4: Ashraful Haq | P4: 3 | Q4: 45033 | R4: 45040 | W4: mdrakibulhasan141084@gmail.com | X4: 1762033779 | Z4: Sonia Akther | AA4: 1705307521 | AB4: Sister | AC4: A+ | AD4: 37111 | AE4: =((TODAY())-AD4)/365 -> 23.523288 | AF4: Islam | AG4: 8713943432 | AH4: N/A | AI4: H.S.C | AJ4: BBA Running | AK4: 2027 | AL4: Dhaka International University (DIU) | AM4: Md. Abul Hosen | AN4: Razia Begum | AO4: Area: House no :312 , block:03 , Ershad nagar thana: Tongi , Dist : Gazipur | AP4: Vill: Motoin , Thana:Senbhag Dist : Dhaka | AQ4: Tongi | AR4: Unmarried | BA4: Active | BB4: 10800 | BC4: 2700 | BD4: 0 | BE4: Morning | BF4: 160230 | BG4: Netstar | BH4: Done | BJ4: rakibul.hasan@genex.com.bd
A5: 171046 | C5: mmaigenex001 | D5: Abu Huraira | E5: Male | F5: 1410873646 | G5: CSO | H5: Content Moderator | I5: Operations | J5: Content Moderation and Data Annotation | K5: TEMU | L5: Fixed | M5: Halima akter | N5: Asif Iqbal | O5: Ashraful Haq | P5: 3 | Q5: 45033 | R5: 45040 | W5: huru5887@gmail.com | X5: 1991760252 | Z5: Nazma Begum | AA5: 1941684125 | AB5: Mother | AC5: B+ | AD5: 37552 | AE5: =((TODAY())-AD5)/365 -> 22.315068 | AF5: Islam | AG5: 1514915337 | AH5: N/A | AI5: H.S.C | AJ5: BBA Running | AK5: 2024 | AL5: Kanchkura University College | AM5: Abu Bakkar Siddik | AN5: Nazma Begum | AO5: Area : 47 No word, Counsellor office, Faidabad,Thana : Dhakshinkhan, Dist : Dhaka-1230 | AP5: Vill : Dhanghura, Thana: Kolarua, Dist : Satkhira | AQ5: Dhakshinkhan | AR5: Unmarried | BA5: Active | BB5: 10800 | BC5: 2700 | BD5: 0 | BE5: Morning | BF5: 161096 | BG5: Netstar | BH5: Done | BJ5: abu.huraira@genex.com.bd
A6: 171061 | C6: mmaigenex021 | D6: Rakiba Akter | E6: Female | F6: 1310512668 | G6: CSO | H6: Content Moderator | I6: Operations | J6: Content Moderation and Data Annotation | K6: TEMU | L6: Fixed | M6: Nazimuddoula Leon | N6: Asif Iqbal | O6: Ashraful Haq | P6: 3 | Q6: 45033 | R6: 45064 | W6: evaemi67@gmail.com | X6: 1874098722 | Y6: 1936508476 | Z6: Gazi Emdadul | AA6: 1725943061 | AB6: Cousin | AC6: B+ | AD6: 36794 | AE6: =((TODAY())-AD6)/365 -> 24.391781 | AF6: Islam | AG6: 3764469205 | AH6: N/A | AI6: H.S.C | AJ6: BSc Running | AK6: 2024 | AL6: Hazi Asmat College | AM6: Shafiullah Khan | AN6: Lacky Begum | AO6: Area : House 1,Road10,Nikunjo 2, Thana: khilkhet,Dist : Dhaka | AP6: Vill: Tekpara , Thana : Belabo, Dist : Narsingdi | AQ6: khilkhet | AR6: Unmarried | BA6: Active | BB6: 10800 | BC6: 2700 | BD6: 0 | BE6: Morning | BF6: 161316 | BG6: Netstar | BH6: Done | BJ6: rikiba.akter@genex.com.bd
A7: 171070 | C7: Genex010 | D7: MD. Ashraf Uddin | E7: Male | F7: 1115216787 | G7: CSO | H7: Content Moderator | I7: Operations | J7: BG Platform Governance Requirements | K7: TEMU | L7: Fixed | M7: Nasir Uddin | N7: Asif Iqbal | O7: Ashraful Haq | P7: 8 | Q7: 45077 | R7: 45093 | W7: asrminhaz@gmail.com | X7: 1580817238 | Z7: MD. Bahauddin Talukder | AA7: 1771487331 | AB7: Father | AC7: O+ | AD7: 36050 | AE7: =((TODAY())-AD7)/365 -> 26.430137 | AF7: Islam | AG7: 7802264635 | AH7: EA0164041 | AI7: B.S.C | AJ7: N/A | AK7: N/A | AL7: Primeasia University | AM7: MD. Bahauddin Talukder | AN7: Ayesha Parvin Chowdhury | AO7: Area : Kuba Mosjid Road,Mohammadpur ,Thana : Bosila Dist : Dhaka | AP7: HOUSE: Bahauddin Talukder house,helipad road,Daulat Khan 8310, Thana: Daulat khan , Dist : Bhola | AQ7: Bosila | AR7: Unmarried | BA7: Active | BB7: 10800 | BC7: 2700 | BD7: 1000 | BE7: Evening | BF7: - | BG7: - | BH7: Done | BJ7: N/A
A8: 171079 | C8: Genex021 | D8: Md. Ismail Hossain | E8: Male | F8: 1010997028 | G8: CSO | H8: Content Moderator | I8: Operations | J8: BG Platform Governance Requirements | K8: TEMU | L8: Fixed | M8: Abu MD. Rifat Imtiaz | N8: Asif Iqbal | O8: Ashraful Haq | P8: 8 | Q8: 45077 | R8: 45090 | W8: mdismailsiraji18@gmail.com | X8: 1823686283 | Y8: 1838419319 | Z8: MD Mowazzem Hossain | AA8: 1904450040 | AB8: Father | AC8: O+ | AD8: 35942 | AE8: =((TODAY())-AD8)/365 -> 26.726027 | AF8: Islam | AG8: 3305207247 | AH8: N/A | AI8: B.S.C | AJ8: N/A | AK8: N/A | AL8: Primeasia University | AM8: Md Mowazzem Hossain | AN8: Mst Honufa Begum | AO8: Area : Road:05, House No:142 Korail T & T Colony Banani Dhaka 1213 , Thana : Banani Dist : Dhaka | AP8: VILL : Chakshahabdi , Thana : Sherpur , Dist : Sherpur | AQ8: Banani | AR8: Married | AS8: Mst Sanjida Akter Lima | AT8: 37814 | BA8: Active | BB8: 10800 | BC8: 2700 | BD8: 1000 | BE8: Evening | BF8: - | BG8: - | BH8: Done | BJ8: N/A
A9: 171080 | C9: Genex022 | D9: Shah Mohammad Yasin | E9: Male | F9: 409458 | G9: CSO | H9: Content Moderator | I9: Operations | J9: BG Platform Governance Requirements | K9: TEMU | L9: Fixed | M9: Mohammad Joshim | N9: Asif Iqbal | O9: Ashraful Haq | P9: 8 | Q9: 45077 | R9: 45093 | W9: Smyasin01@gmail.com | X9: 1533970670 | Y9: 1838801744 | Z9: Isran Jahan Ripa | AA9: 1737029346 | AB9: Wife | AC9: AB+ | AD9: 34860 | AE9: =((TODAY())-AD9)/365 -> 29.690411 | AF9: Islam | AG9: 3278966514 | AH9: N/A | AI9: B.B.A | AJ9: N/A | AK9: N/A | AL9: Daffodil International University | AM9: Shah Mohammad Almas | AN9: Hazera Begum | AO9: Area : H-16,R-15,Nikunjo-2,Thana : khilkhet ,Dist : Dhaka | AP9: Vill: lakherraj kosba Thana : Gournodi , Dist : Barishal. | AQ9: Khilkhet | AR9: Married | AS9: Israt Jahan Ripa | AT9: 36974 | BA9: Active | BB9: 10800 | BC9: 2700 | BD9: 1000 | BE9: Evening | BF9: - | BG9: - | BH9: Done | BJ9: N/A
A10: 171083 | C10: Genex025 | D10: Md. Shamim Hossain | E10: Male | F10: 983930 | G10: CSO | H10: Content Moderator | I10: Operations | J10: BG Platform Governance Requirements | K10: TEMU | L10: Fixed | M10: Rakib Ahsan | N10: Asif Iqbal | O10: Ashraful Haq | P10: 8 | Q10: 45077 | R10: 45090 | W10: Shamimhossain2328@gmai.com | X10: 1918182328 | Y10: 1677266500 | Z10: Shahana begum | AA10: 1772074726 | AB10: Mother | AC10: O+ | AD10: 34611 | AE10: =((TODAY())-AD10)/365 -> 30.372603 | AF10: Islam | AG10: 1.9943923e+16 | AH10: N/A | AI10: B.B.A | AJ10: N/A | AK10: N/A | AL10: National university | AM10: Md Abdullah | AN10: Shahana | AO10: Area : House 7, Road 10, Block C. Banarsrce, Thana : Rampura,Dist : Dhaka | AP10: Vill : South Doriabad,Thana: islampur, Dist : Jamalpur | AQ10: Rampura | AR10: Unmarried | BA10: Active | BB10: 10800 | BC10: 2700 | BD10: 1000 | BE10: Evening | BF10: - | BG10: - | BH10: Done | BJ10: N/A
A11: 171084 | C11: Genex026 | D11: Gulzer Hossain | E11: Male | F11: 444434 | G11: CSO | H11: Content Moderator | I11: Operations | J11: BG Platform Governance Requirements | K11: TEMU | L11: Fixed | M11: Mohammad Joshim | N11: Asif Iqbal | O11: Ashraful Haq | P11: 8 | Q11: 45077 | R11: 45090 | W11: gulzer853@gmail.com | X11: 1763369092 | Y11: 1942908139 | Z11: Gulshan Ara | AA11: 1674937436 | AB11: Mother | AC11: A+ | AD11: 35005 | AE11: =((TODAY())-AD11)/365 -> 29.293151 | AF11: Islam | AG11: 3269692459 | AH11: N/A | AI11: M.S.S | AJ11: N/A | AK11: N/A | AL11: National University | AM11: Aliul Hossain | AN11: Gulshan Ara | AO11: Vill: Darirampur, Poura word no: 9, Post office: Trishal, District: Mymensingh. | AP11: Vill: Darirampur, Poura word no: 9, Post office: Trishal, District: Mymensingh. | AQ11: Darirampur, Mymensingh. | AR11: Unmarried | BA11: Active | BB11: 10800 | BC11: 2700 | BD11: 1000 | BE11: Evening | BF11: - | BG11: - | BH11: Done | BJ11: N/A
A12: 171088 | D12: Md. Ataur Rahman | E12: Male | F12: 753417 | G12: CSO | H12: Content Moderator | I12: Operations | J12: Identification of the same product | K12: TEMU | L12: Fixed | M12: Halima akter | N12: Asif Iqbal | O12: Ashraful Haq | P12: 10 | Q12: 45110 | R12: 45113 | W12: eco.ataur@gmail.com | X12: 1575014017 | Y12: 1642428374 | Z12: Mst Jayeda Begum | AA12: 1724227590 | AB12: Sister | AC12: O+ | AD12: 35642 | AE12: =((TODAY())-AD12)/365 -> 27.547945 | AF12: Islam | AG12: 1951661667 | AH12: N/A | AI12: BSS | AJ12: N/A | AK12: N/A | AL12: Govt Titumir College | AM12: Abdul Khalek Hawlader | AN12: Hasina Begum | AO12: House- Kha-110/1; South Badda; Badda; Dhaka. | AP12: Vill: Gopkhali; Post: South Chandokhali; PS: Patuakhali; Dist: Patuakhali. | AQ12: Badda | AR12: Unmarried | BA12: Active | BB12: 10800 | BC12: 2700 | BD12: 0 | BE12: Morning | BF12: - | BG12: - | BH12: Done | BJ12: N/A
A13: 171101 | D13: Mohammad Joshim | E13: Male | F13: 665061 | G13: Executive | H13: Team Leader | I13: Operations | J13: Identification of the same product | K13: TEMU | L13: Fixed | M13: Rakib Ahsan | N13: Asif Iqbal | O13: Ashraful Haq | P13: 10 | Q13: 45110 | R13: 45113 | S13: 45367 | W13: mohammadjashim171@gmail.com | X13: 1909686492 | Y13: 1909686497 | Z13: Kajol Begum | AA13: 1734836888 | AB13: Mother | AC13: AB+ | AD13: 34996 | AE13: =((TODAY())-AD13)/365 -> 29.317808 | AF13: Islam | AG13: 2356972600 | AH13: N/A | AI13: B.A. | AJ13: N/A | AK13: N/A | AL13: Government Titumir college | AM13: Mohammad Shohidul Islam | AN13: Kajol Begum | AO13: House- 555, East Badda, Dhaka-1212 | AP13: Village: ayla, dis+po: Munshiganj Sadar | AQ13: Badda | AR13: Unmarried | BA13: Active | BB13: 14500 | BC13: 3500 | BD13: 2000 | BE13: Evening | BF13: - | BG13: - | BH13: Done | BJ13: m.joshim@genex.com.bd
A14: 171113 | C14: mmaigenex047 | D14: Rakibul Alam | E14: Male | F14: 941507 | G14: CSO | H14: Content Moderator | I14: Operations | J14: Natural Language Process | K14: TEMU | L14: Fixed | M14: Mizanur Rahman | N14: Asif iqbal | O14: Ashraful Haq | P14: 11 | Q14: 45116 | R14: 45124 | W14: rakibkhan9020@gmail.com | X14: 1819492684 | Y14: 1684640110 | Z14: Jabun Nesa Begum | AA14: 1684640110 | AB14: Mother | AC14: O+ | AD14: 35784 | AE14: =((TODAY())-AD14)/365 -> 27.158904 | AF14: Islam | AG14: 2402200170 | AH14: N/A | AI14: M.B.A | AJ14: N/A | AK14: NA | AL14: Dhaka College (Dhaka University) | AM14: Abul Kashem Mahamud Alam | AN14: Jabun Nesa Begum | AO14: Area :House- A,68/9,East Rajason ,Birulia Road, Thana: Savar Dist :Dhaka | AP14: House- A,68/9,East Rajason ,Birulia Road, Savar,Dhaka | AQ14: Savar | AR14: Unmarried | BA14: Active | BB14: 10800 | BC14: 2700 | BD14: 0 | BE14: Morning | BF14: - | BG14: - | BH14: Done | BJ14: N/A
A15: 171116 | C15: xushiyu5op | D15: Md. Zahidul Islam | E15: Male | F15: 869701 | G15: CSO | H15: Content Moderator | I15: Operations | J15: Identification of the same product | K15: TEMU | L15: Fixed | M15: Mizanur Rahman | N15: Asif iqbal | O15: Ashraful Haq | P15: 11 | Q15: 45116 | R15: 45121 | W15: sszahidulislam61@gmail.com | X15: 1944875561 | Y15: 1689-091587 | Z15: Brother | AA15: 1689-091587 | AB15: Brother | AC15: O+ | AD15: 35289 | AE15: =((TODAY())-AD15)/365 -> 28.515068 | AF15: Islam | AG15: 8711787646 | AH15: N/A | AI15: BA | AJ15: MA | AK15: 2023 | AL15: Tongi govt.college | AM15: Amzad hossain | AN15: Halima begum | AO15: Vill : Daudpur, Thana: rupganj, Dist : Narayanganj | AP15: Vill : Daudpur, Thana: rupganj, Dist : Narayanganj | AQ15: Rupganj | AR15: Single | BA15: Active | BB15: 10800 | BC15: 2700 | BD15: 0 | BE15: Morning | BF15: - | BG15: - | BH15: Done | BJ15: N/A
A16: 171117 | C16: zhulan5op | D16: Md. Shazib Miah | E16: Male | F16: 869625 | G16: CSO | H16: Content Moderator | I16: Operations | J16: Identification of the same product | K16: TEMU | L16: Fixed | M16: Nazimuddoula Leon | N16: Asif iqbal | O16: Ashraful Haq | P16: 11 | Q16: 45116 | R16: 45121 | W16: ahnedsajib@gmail.com | X16: 1627393180 | Y16: 1922920547 | Z16: Rafiqul Islam | AA16: 1641845257 | AB16: Brother | AC16: A+ | AD16: 35407 | AE16: =((TODAY())-AD16)/365 -> 28.191781 | AF16: Islam | AG16: 8685695705 | AH16: N/A | AI16: MBA | AJ16: N/A | AK16: N/A | AL16: AKM Rhamutullah University & Collage | AM16: Ahammad Ali | AN16: Mamotaj | AO16: Vill : Beldi; Thana: Rupganj; Dist : Narayanganj | AP16: Vill : Beldi; Thana: Rupganj; Dist : Narayanganj | AQ16: Rupganj | AR16: Single | BA16: Active | BB16: 10800 | BC16: 2700 | BD16: 0 | BE16: Morning | BF16: - | BG16: - | BH16: Done | BJ16: N/A
A17: 171135 | C17: Genex032 | D17: Md. Tanjir Ahmed | E17: Male | F17: 1310589431 | G17: Executive | H17: Team Leader | I17: Operations | J17: BG Platform Governance Requirements | K17: TEMU | L17: Fixed | M17: Asif Iqbal | O17: Ashraful Haq | P17: 13 | Q17: 45154 | R17: 45163 | S17: 45459 | V17: 1847270310 | W17: tanjirahmed.uibt@gmail.com | X17: 1628439640 | Y17: 1327275514 | Z17: Rokshana Islam | AA17: 1818371637 | AB17: Aunty | AC17: A+ | AD17: 36755 | AE17: =((TODAY())-AD17)/365 -> 24.49863 | AF17: Islam | AG17: 871495 9916 | AH17: EE 0135811 | AI17: HSC | AJ17: CSE | AK17: 2023 | AL17: Uttara Institute of Business & Technology | AM17: Md Johirul Islam | AN17: Tahmina Begum | AO17: , House: 33, Road: 11, Sector: 12, Uttara, Dhaka-1230 | AP17: Vill: Rasulpur, PO: Payali, PS: Matlab South, Dist: Chandpur | AQ17: Uttara | AR17: Single | BA17: Active | BB17: 14500 | BC17: 3500 | BD17: 2000 | BE17: Evening | BF17: 160350 | BG17: Netstar | BH17: Done | BJ17: tanjir.ahmed@genex.com.bd
A18: 171160 | D18: Abdulla Al Mamun | E18: Male | F18: 666193 | G18: Executive | H18: Team Leader | I18: Operations | J18: Identification of the same product | K18: TEMU | L18: Fixed | M18: Asif Iqbal | N18: Asif Iqbal | O18: Ashraful Haq | P18: 16 | Q18: 45206 | R18: 45215 | W18: abdullah.mamunch@gmail.com | X18: 1714517836 | Y18: 1867547635 | Z18: Kuntum Khaira | AA18: 1731819698 | AB18: Wife | AC18: A+ | AD18: 35226 | AE18: =((TODAY())-AD18)/365 -> 28.687671 | AF18: Islam | AG18: 1003812771 | AH18: N/A | AI18: BSC | AJ18: N/A | AK18: 2020 | AL18: American International University-Bangladesh | AM18: MD.Nuruzzaman | AN18: MST. Rozina Parvin | AO18: House-KA/24-2, Road- Bazar Road, Khilkhet, Dhaka, 1229 | AP18: Choto Shalika, Notun Bazar, Chatmohor, 6630, Pabna | AQ18: khilkhet | AR18: Married | AS18: Kuntum Khaira | BA18: Active | BB18: 14500 | BC18: 3500 | BD18: 0 | BE18: Morning | BH18: Done
A19: 171161 | D19: Kuntum Khaira | E19: Female | F19: 1112805345 | G19: CSO | H19: Content Moderator | I19: Operations | J19: Home 2 | K19: TEMU | L19: Fixed | M19: Halima akter | N19: Asif Iqbal | O19: Ashraful Haq | P19: 16 | Q19: 45206 | R19: 45211 | W19: kn2mkhr@gmail.com | X19: 1731819698 | Y19: 1521705675 | Z19: Abdulla Al Mamun | AA19: 1714517836 | AB19: Husband | AC19: O+ | AD19: 36083 | AE19: =((TODAY())-AD19)/365 -> 26.339726 | AF19: Islam | AG19: 8254540548 | AH19: N/A | AI19: BSC | AJ19: M.Sc. | AK19: 2023 | AL19: Govt. College of Applied Human Science | AM19: MD. Asraful Alam | AN19: MST. Sultana Jannatul Ferdose | AO19: House - Ka-24/2, Khilkhet Bazar Road, Khilkhet,Dhaka 1223 | AP19: House-168, Road- Kazipara. Chatmohar-6630,Chatmohar,Pabna | AQ19: Khilkhet | AR19: Married | AS19: Abdulla Al Mamun | BA19: Active | BB19: 10800 | BC19: 2700 | BD19: 0 | BE19: Morning | BH19: Done
A20: 171163 | C20: zhulan13op | D20: Md. Saydur Rahman | E20: Male | F20: 397830 | G20: CSO | H20: Content Moderator | I20: Operations | J20: Beauty & accessory | K20: TEMU | L20: Fixed | M20: Nazmus Sakib | N20: Asif Iqbal | O20: Ashraful Haq | P20: 16 | Q20: 45207 | R20: 45211 | W20: mdsayedurrahman587@gmail.com | X20: 1736204330 | Y20: 1934816042 | Z20: Sabrina Aktar | AA20: 1934816042 | AB20: Niece | AC20: B+ | AD20: 34315 | AE20: =((TODAY())-AD20)/365 -> 31.183562 | AF20: Islam | AG20: 9561555658 | AH20: N/A | AI20: Masters | AJ20: N/A | AK20: 2023 | AL20: Govt. Bangla College | AM20: Mohammad Solaiman | AN20: Hasina Begum | AO20: Nikunja 2, House 18, road 1/B | AP20: Village : Folshi, PO: Nizamkandi, Thana: Kashiyani, District : Gopalgonj | AQ20: Nikunja 2 | AR20: Unmarried | BA20: Active | BB20: 10800 | BC20: 2700 | BD20: 0 | BE20: Morning | BH20: Done
A21: 171168 | D21: Alya Tunjum Momo | E21: Female | F21: 1010895851 | G21: CSO | H21: Content Moderator | I21: Operations | J21: Home 1 | K21: TEMU | L21: Fixed | M21: Halima akter | N21: Asif Iqbal | O21: Ashraful Haq | P21: 16 | Q21: 45206 | R21: 45211 | W21: alyamomo96@gmail.com | X21: 1626817339 | Z21: Jahanara | AA21: 1951741116 | AB21: Mother | AC21: B+ | AD21: 35373 | AE21: =((TODAY())-AD21)/365 -> 28.284932 | AF21: Islam | AG21: 6452970400 | AH21: N/A | AI21: BBA | AJ21: N/A | AK21: 2019 | AL21: Uttara university | AM21: Late Mishba Uddin | AN21: Jahanara Begum | AO21: House -8,Bonomala, Tongi college gat, Tongi, Gazipur -1712 | AP21: Bonomala,Dottopara,post-1712, Gazipur sodor, Gazipur city corporation, Gazipur | AQ21: Tongi | AR21: Single | BA21: Active | BB21: 10800 | BC21: 2700 | BD21: 0 | BE21: Morning | BH21: Done
A22: 171170 | C22: zhulan7op | D22: Sumsun Naher Shimu | E22: Female | F22: 1110152653 | G22: CSO | H22: Content Moderator | I22: Operations | J22: Beauty & accessory | K22: TEMU | L22: Fixed | M22: Nazimuddoula Leon | N22: Asif Iqbal | O22: Ashraful Haq | P22: 16 | Q22: 45206 | R22: 45211 | W22: shumsunnaher24@gmail.com | X22: 1853069639 | Y22: 1872366337 | Z22: Father | AA22: 1816111194 | AB22: Father | AC22: O+ | AD22: 35533 | AE22: =((TODAY())-AD22)/365 -> 27.846575 | AF22: Islam | AG22: 6451816927 | AH22: N/A | AI22: Honour's | AJ22: Master’s | AK22: 2020 | AL22: Uttara Town College | AM22: MD.Sirajul Islam | AN22: Selina Akter | AO22: House:F5/1,kawlar CAAB staff quarters, Kurmitola Dhaka -1229 | AP22: Vill:Mollapara mahutola,Thanarhat joyag,Sonaimuri, Noakhali. | AQ22: Kawlar | AR22: Unmarried | BA22: Active | BB22: 10800 | BC22: 2700 | BD22: 0 | BE22: Morning | BH22: Done
A23: 171173 | C23: naihe12op | D23: Pial Ahmed | E23: Male | F23: 1310262823 | G23: CSO | H23: Content Moderator | I23: Operations | J23: Sports & shoes & bags & special women clothing | K23: TEMU | L23: Fixed | M23: Md Mehedi Hasan | N23: Asif Iqbal | O23: Ashraful Haq | P23: 16 | Q23: 45206 | R23: 45211 | W23: pial.ahmed512@gmail.com | X23: 1618393569 | Z23: yasin shah | AA23: 1838801744 | AB23: Brother | AC23: O+ | AD23: 36031 | AE23: =((TODAY())-AD23)/365 -> 26.482192 | AF23: Islam | AG23: 19980719485028800 | AH23: N/A | AI23: Honours | AJ23: N/A | AK23: 2022 | AL23: Government titumir college | AM23: Mahfuzur Rahman | AN23: Khadiza Akter | AO23: H#08, R#19, Nikunjo-2 Khilkhet | AP23: Atahargonj, Barishal Sadar Barishal | AQ23: Nikunjo | AR23: Unmarried | BA23: Active | BB23: 10800 | BC23: 2700 | BD23: 0 | BE23: Morning | BH23: Done
A24: 171181 | C24: xisailuo14op | D24: Tithi Rani Kundu | E24: FEMALE | F24: 701608 | G24: CSO | H24: Content Moderator | I24: Operations | J24: Home 1 | K24: TEMU | L24: Fixed | M24: Halima akter | N24: Asif Iqbal | O24: Ashraful Haq | P24: 16 | Q24: 45207 | R24: 45211 | W24: tithikundu2023@gmail.com | X24: 1752483561 | Y24: 1713742583 | Z24: KRISNA KUMAR KUNDU | AA24: 1713742583 | AB24: FATHER | AC24: B+ | AD24: 34405 | AE24: =((TODAY())-AD24)/365 -> 30.936986 | AF24: Hindu | AG24: 1.9947618e+16 | AH24: N/A | AI24: POST GRADUATION | AJ24: N/A | AK24: 2016 | AL24: GOVT. EDWARD COLLEGE,PABNA | AM24: KRISNA KUMAR KUNDU | AN24: ITI RANI KUNDU | AO24: HOUSE:138/KHA,JAMTALA,TANPARA,KHILKHET,NIKUNJA-2,DHAKA-1229 | AP24: VILLAGE:SAGARKANDI,POST:SAGARKANDI,POST CODE:6661,UPAZILLA:SUJA NAGAR,DISTRICT:PABNA | AQ24: KHILKHET | AR24: MARRIED | AS24: SREE ROMENDRONATH | BA24: Active | BB24: 10800 | BC24: 2700 | BD24: 0 | BE24: Morning | BH24: Done
A25: 171182 | D25: Aminul Islam Sovo | E25: Male | F25: 1210692310 | G25: Executive | H25: Team Leader | I25: Operations | J25: Identification of the same product | K25: TEMU | L25: Fixed | M25: Asif Iqbal | N25: Asif Iqbal | O25: Ashraful Haq | P25: 16 | Q25: 45207 | R25: 45211 | W25: shuvoahmed4466@gmail.com | X25: 1732784466 | Y25: 1964547614 | Z25: Monowar Hossain | AA25: 1575500082 | AB25: Brother | AC25: O+ | AD25: 36160 | AE25: =((TODAY())-AD25)/365 -> 26.128767 | AF25: Islam | AG25: 8708000057 | AH25: N/A | AI25: BSC | AJ25: N/A | AK25: 2023 | AL25: Stamford University Bangladesh | AM25: Md. Afjal Hossen | AN25: Majeda Begum | AO25: House: 30/2 , kadamtala school road, Basabo, Dhaka-1214 | AP25: House: Madber bari, Vill: Madber kandi, Post: Balarhat(8030) Ps: Shakhipur, Dist: Shariatpur | AQ25: Basabo | AR25: Unmarried | BA25: Active | BB25: 14500 | BC25: 3500 | BD25: 0 | BE25: Morning | BH25: Done
A26: 171186 | C26: xisailuo8op | D26: MD. Masum Billah | E26: Male | F26: 1013134916 | G26: CSO | H26: Content Moderator | I26: Operations | J26: Home 2 | K26: TEMU | L26: Fixed | M26: Halima akter | N26: Asif Iqbal | O26: Ashraful Haq | P26: 16 | Q26: 45208 | R26: 45211 | W26: masum01771744@gmail.com | X26: 1771744281 | Y26: 1910826006 | Z26: Saddam Hossain | AA26: 1787440266 | AB26: Friend | AC26: B+ | AD26: 35432 | AE26: =((TODAY())-AD26)/365 -> 28.123288 | AF26: Islam | AG26: 8706441071 | AH26: N/A | AI26: MA | AJ26: N/A | AK26: 2020 | AL26: Govt. Rajendra college | AM26: Mir Shalauddin | AN26: Mst.Shahanara Begum | AO26: Nikunja-2,Road No-05,House No-kha-50,Khilkhet, Dhaka-1229. | AP26: Jibannagar, Chuadanga | AQ26: Khilkhet | AR26: Unmarried | BA26: Active | BB26: 10800 | BC26: 2700 | BD26: 0 | BE26: Morning | BH26: Done
A27: 171189 | C27: heibulin14op | D27: Sharmin Jahan | E27: Female | F27: 944413 | G27: CSO | H27: Content Moderator | I27: Operations | J27: Home 2 | K27: TEMU | L27: Fixed | M27: Mizanur Rahman | N27: Asif Iqbal | O27: Ashraful Haq | P27: 16 | Q27: 45208 | R27: 45211 | W27: msrdiya60@gmail.com | X27: 1999223191 | Z27: Taslima begum | AA27: 1402517624 | AB27: Aunty | AC27: A+ | AD27: 35718 | AE27: =((TODAY())-AD27)/365 -> 27.339726 | AF27: Islam | AG27: 2853835862 | AH27: N/A | AI27: BBA | AJ27: N/A | AK27: 2018 | AL27: Gvt.gurudayal college, kishoreganj | AM27: MD. Sahidullah | AN27: MST. Zarana | AO27: House:19, Road:08, Nikunja-02, Dhaka-1229 | AP27: Vill:Kuttragor, po:chorpumdi, Ps:kishoreganj, Dis:Kishoreganj | AQ27: Nikunja-02 | AR27: Unmarried | BA27: Active | BB27: 10800 | BC27: 2700 | BD27: 0 | BE27: Morning | BH27: Done
A28: 171191 | C28: xisailuo7op | D28: Shahanaz Akter Brishty | E28: Female | F28: 1111472238 | G28: CSO | H28: Content Moderator | I28: Operations | J28: Home 1 | K28: TEMU | L28: Fixed | M28: Halima akter | N28: Asif Iqbal | O28: Ashraful Haq | P28: 16 | Q28: 45208 | R28: 45211 | W28: Odhorabristi178@gmail.com | X28: 1728198067 | Z28: Sadia Afrin Prithibi | AA28: 1810845234 | AB28: Sister | AC28: B+ | AD28: 36390 | AE28: =((TODAY())-AD28)/365 -> 25.49863 | AF28: Islam | AG28: 7365611347 | AH28: N/A | AI28: Honours | AJ28: N/A | AK28: 2020 | AL28: Chinair Bangabandhu Sheikh Mujib Degree College | AM28: Shahin Bhuiyan | AN28: Nazma Begum | AO28: H#11,R#10,Sector#9, Uttara, Dhaka | AP28: H#1241,kawtoly, Brahmanbaria | AQ28: Uttara | AR28: Unmarried | BA28: Active | BB28: 10800 | BC28: 2700 | BD28: 0 | BE28: Morning | BH28: Done
A29: 171192 | D29: Nasrin Akter | E29: Female | F29: 1110583805 | G29: CSO | H29: Content Moderator | I29: Operations | J29: Product's Review for Risk Control | K29: TEMU | L29: Fixed | M29: Halima akter | N29: Asif Iqbal | O29: Ashraful Haq | P29: 17 | Q29: 45224 | R29: 45235 | W29: nrupa2973@gmail.com | X29: 1629133146 | Z29: Abdullah Al Mamun | AA29: 1682823507 | AB29: Spouse | AC29: B+ | AD29: 36130 | AE29: =((TODAY())-AD29)/365 -> 26.210959 | AF29: Islam | AG29: 6454397537 | AH29: A07811108 | AI29: BBA | AJ29: N/A | AL29: International University of Business Agriculture and Technology | AM29: Md. Abul Kashem | AN29: Mrs. Asma Akter | AO29: House- 104 West Mollartek Dhakkhinkhan Dhaka- | AP29: House-113, Road- Hazi unos ali sarker road, uttar arichpur, PO-1710 Gazipur | AQ29: Dhakkhinkhan | AR29: Married | AS29: Abdullah Al Mamun | AT29: 34670 | AU29: N/A | AV29: N/A | BA29: Active | BB29: 10800 | BC29: 2700 | BD29: 0 | BE29: Morning | BH29: Done
A30: 171195 | D30: Flora Tanbin | E30: Female | F30: 1115244614 | G30: CSO | H30: Content Moderator | I30: Operations | J30: Home 1 | K30: TEMU | L30: Fixed | M30: Mizanur Rahman | N30: Asif Iqbal | O30: Ashraful Haq | P30: 17 | Q30: 45225 | R30: 45235 | W30: Floratanbin@gmail.com | X30: 1823369317 | Y30: 1631128694 | Z30: Husband | AA30: 1881338680 | AB30: Good | AC30: B+ | AD30: 36502 | AE30: =((TODAY())-AD30)/365 -> 25.191781 | AF30: Islam | AG30: 4654159088 | AH30: N/A | AI30: Graduated | AJ30: Post graduated | AK30: 2020 | AL30: Eden mohila College | AM30: Abul kalam mia | AN30: Selina Begum | AO30: Azimpur, Dhaka | AP30: Gournodi upazila,village -katakstall,district -Barisal. | AQ30: Azimpur | AR30: Married | AS30: Yesin arafat asif | AT30: 35952 | AU30: N/A | AV30: N/A | BA30: Active | BB30: 10800 | BC30: 2700 | BD30: 0 | BE30: Morning | BH30: Done
A31: 171196 | D31: Mukti Afroz | E31: Female | F31: 221315 | G31: CSO | H31: Content Moderator | I31: Operations | J31: Beauty & accessory | K31: TEMU | L31: Fixed | M31: Nazimuddoula Leon | N31: Asif Iqbal | O31: Ashraful Haq | P31: 17 | Q31: 45224 | R31: 45235 | W31: afroj.sohag26@gmail.com | X31: 1306777070 | Y31: 1782618205 | Z31: Md:Abu Jahid | AA31: 1782618205 | AB31: SPOUSE | AC31: O+ | AD31: 34039 | AE31: =((TODAY())-AD31)/365 -> 31.939726 | AF31: Islam | AG31: 6464967550 | AH31: N/A | AI31: MA | AJ31: N/A | AK31: 2015 | AL31: Govt: Rajendro College Faridpur | AM31: Md: Abdul Aziz | AN31: Jahanara Begum | AO31: PWD Staff Quarter,Tejgoan,Dhaka. | AP31: Vill:Charjhikori, po:Kacharipara up:pangsha dist:Rajbari | AQ31: Tejgoan | AR31: Married | AS31: Md: Abu Jahid | AU31: N/A | AV31: N/A | BA31: Active | BB31: 10800 | BC31: 2700 | BD31: 0 | BE31: Morning | BH31: Done
A32: 171219 | C32: Genex074 | D32: Mahmudul Hasan | E32: Male | F32: 1210880961 | G32: CSO | H32: Content Moderator | I32: Operations | J32: BG Platform Governance Requirements | K32: TEMU | L32: Fixed | M32: Md. Tanjir Ahmed | N32: Asif Iqbal | O32: Ashraful Haq | P32: 18 | Q32: 45246 | R32: 45265 | W32: mahmudulhasanroniprofessional@gmail.com | X32: 1793931848 | Z32: Nurul Alam | AA32: 1819671474 | AB32: Father | AC32: O+ | AD32: 36474 | AE32: =((TODAY())-AD32)/365 -> 25.268493 | AF32: Islam | AG32: 7804447634 | AH32: N/A | AI32: Honours | AJ32: N/A | AK32: 2022 | AL32: Primeasia University | AM32: Nurul Alam | AN32: Nur Nahar | AO32: Holding no: 117, uttar Datta para ,tongi gazipur | AP32: Holding no:117, Uttar datta para tongi gazipur ,1712 | AQ32: Gazipur | AR32: Unmarried | AS32: N/A | AT32: N/A | AU32: N/A | AV32: N/A | AW32: N/A | AX32: N/A | BA32: Active | BB32: 10800 | BC32: 2700 | BD32: 1000 | BE32: Evening | BH32: Done
A33: 171233 | C33: Genex077 | D33: Shohidullah | E33: Male | F33: 1110225403 | G33: CSO | H33: Content Moderator | I33: Operations | J33: BG Platform Governance Requirements | K33: TEMU | L33: Fixed | M33: Mohammad Joshim | N33: Asif Iqbal | O33: Ashraful Haq | P33: 18 | Q33: 45246 | R33: 45264 | W33: mahmudulhasanroniprofessional@gmail.com | X33: 1521124841 | Z33: Md. Shahidullah | AA33: 1954090450 | AB33: Father | AC33: O+ | AD33: 36028 | AE33: =((TODAY())-AD33)/365 -> 26.490411 | AF33: Islam | AG33: 6454317246 | AH33: N/A | AI33: BSC | AJ33: N/A | AK33: 2020 | AL33: Mohammadpur central University college | AM33: Md. Shahidullah | AN33: Sayeda Begum | AO33: Livestock Research Institute,, Jamuna-206,Mohakhali,Dhaka-1212 | AP33: Vill: Saraspur, Post: Khamer-1730,Thana: Kapasia,Dist: Gazipur | AQ33: Mohakhali | AR33: Unmarried | AS33: N/A | AT33: N/A | AU33: N/A | AV33: N/A | AW33: N/A | AX33: N/A | BA33: Active | BB33: 10800 | BC33: 2700 | BD33: 1000 | BE33: Evening | BH33: Done
A34: 171244 | D34: Sabrina Sultana Mou | E34: Female | F34: 690864/2010 | G34: Executive | H34: Team Leader | I34: Operations | J34: Identification of the same product | K34: TEMU | L34: Fixed | M34: Asif Iqbal | N34: Asif Iqbal | O34: Ashraful Haq | P34: 19 | Q34: 45251 | R34: 45256 | W34: sabrinmou05@gmail.com | X34: 1626675115 | Z34: Abdur rahman | AA34: 1617677799 | AB34: Husband | AC34: B+ | AD34: 35374 | AE34: =((TODAY())-AD34)/365 -> 28.282192 | AF34: Islam | AG34: 19964817957114800 | AH34: N/A | AI34: M.pharm | AJ34: N/A | AK34: 2022 | AL34: State University of Bangladesh | AM34: Abu daud | AN34: Shahanaz Dilroba | AO34: House-25,road-10,area-Bashaboo,ps-1214,dist-Dhaka | AP34: Vill-Tarakandi,ps-Tarakandi,dist-kishoregonj | AQ34: Bashabo | AR34: Married | AS34: Abdur rahman | AT34: 34907 | AU34: N/A | AV34: N/A | AW34: N/A | AX34: N/A | BA34: Active | BB34: 14500 | BC34: 3500 | BD34: 0 | BE34: Morning | BH34: Done
A35: 171251 | C35: Genex079 | D35: Sabbir Ali | E35: Male | F35: N/A | G35: CSO | H35: Content Moderator | I35: Operations | J35: BG Platform Governance Requirements | K35: TEMU | L35: Fixed | M35: Nasir Uddin | N35: Asif Iqbal | O35: Ashraful Haq | P35: 19 | Q35: 45251 | R35: 45268 | W35: shabbir2380@gmail.com | X35: 1318795129 | Z35: MD Ali | AA35: 1768776161 | AB35: Father | AC35: B+ | AD35: 36335 | AE35: =((TODAY())-AD35)/365 -> 25.649315 | AF35: Islam | AG35: 4655222992 | AH35: N/A | AI35: BBA | AJ35: N/A | AK35: 2023 | AL35: Dr Maleka University | AM35: MD Ali | AN35: Shila Begum | AO35: House number: 16/18 Begum Bazar Area: chawkbazar ps:1211 Dist: Dhaka | AP35: Vill:16/18 Begum Bazar ps:1211 dist: Dhaka | AQ35: 16/18 Begum Bazar | AR35: Unmarried | AS35: N/A | AT35: N/A | AU35: N/A | AV35: N/A | AW35: N/A | AX35: N/A | BA35: Active | BB35: 10800 | BC35: 2700 | BD35: 1000 | BE35: Evening | BH35: Done
A36: 171255 | C36: Genex080 | D36: Md. Fahad Alam | E36: Male | F36: 1210979339 | G36: CSO | H36: Content Moderator | I36: Operations | J36: BG Platform Governance Requirements | K36: TEMU | L36: Fixed | M36: Rakib Ahsan | N36: Asif Iqbal | O36: Ashraful Haq | P36: 19 | Q36: 45251 | R36: 45268 | W36: mdfahadalam109@gmail.com | X36: 1310439784 | Z36: Saiful Alam | AA36: 1710885450 | AB36: Father | AC36: A+ | AD36: 36512 | AE36: =((TODAY())-AD36)/365 -> 25.164384 | AF36: Islam | AG36: 6454925576 | AH36: N/A | AI36: BBA | AJ36: N/A | AK36: 2023 | AL36: Sheikh Borhanuddin Post Graduate College | AM36: MD Saiful Alam | AN36: Asma Alam | AO36: 75/1 Chankherpool Lane, Dhaka-1000 | AP36: 75/1 Chankherpool Lane, Dhaka-1000 | AQ36: Chankherpool Lane | AR36: Unmarried | AS36: N/A | AT36: N/A | AU36: N/A | AV36: N/A | AW36: N/A | AX36: N/A | BA36: Active | BB36: 10800 | BC36: 2700 | BD36: 1000 | BE36: Evening | BH36: Done
A37: 171264 | C37: naihe29op | D37: Antoni Chakma | E37: Female | F37: 868338 | G37: CSO | H37: Content Moderator | I37: Operations | J37: Home 2 | K37: TEMU | L37: Fixed | M37: Md Mehedi Hasan | N37: Asif Iqbal | O37: Ashraful Haq | P37: 19 | Q37: 45251 | R37: 45256 | W37: antanichakma6@gmail.com | X37: 1556746243 | Y37: 1763399247 | Z37: Rabi Jyoti Chakma | AA37: 1556770615 | AB37: Father | AC37: A+ | AD37: 33916 | AE37: =((TODAY())-AD37)/365 -> 32.276712 | AF37: Buddhism | AG37: 19924617776000100 | AH37: N/A | AI37: MPS | AJ37: N/A | AK37: 2019 | AL37: University of Dhaka | AM37: Rabi Jyoti Chakma | AN37: Johtsna Chakma | AO37: Area:Shewrapara, House no: 365, Road, Fakhir bari, Annodhabazar | AP37: Vill: Monju Adam, PO:Panchari, PS: Panchari, Dist: Khagrachhari | AQ37: Mirpur | AR37: Unmarried | AS37: N/A | AT37: N/A | AU37: N/A | AV37: N/A | AW37: N/A | AX37: N/A | BA37: Active | BB37: 10800 | BC37: 2700 | BD37: 0 | BE37: Morning | BH37: Done
A38: 171269 | C38: naihe62op | D38: SK Abu Labib | E38: Male | F38: 1413305509 | G38: CSO | H38: Content Moderator | I38: Operations | J38: Sports & shoes & bags & special women clothing | K38: TEMU | L38: Fixed | M38: Md Mehedi Hasan | N38: Asif Iqbal | O38: Ashraful Haq | P38: 20 | Q38: 45256 | R38: 45261 | W38: skabulabib725225@gmail.com | X38: 1732833401 | Y38: 1827271372 | Z38: Sk Abu Mobin | AA38: 1936313761 | AB38: Father | AC38: A+ | AD38: 36625 | AE38: =((TODAY())-AD38)/365 -> 24.854795 | AF38: Islam | AG38: 6460643205 | AH38: N/A | AI38: BSc in EEE | AJ38: N/A | AK38: 2023 | AL38: American International University - Bangladesh | AM38: Sk Abu Mobin | AN38: Mrs Malaka Mobin | AO38: Road-29,House-38,Rupnagor R/A, Mirpur | AP38: Labsha, Satkhira | AQ38: Mirpur | AR38: Unmarried | AS38: N/A | AT38: N/A | AU38: N/A | AV38: N/A | AW38: N/A | AX38: N/A | BA38: Active | BB38: 10800 | BC38: 2700 | BD38: 0 | BE38: Morning | BH38: Done
A39: 171278 | C39: heibulin28op | D39: Sungida Alam | E39: Female | F39: N/A | G39: CSO | H39: Content Moderator | I39: Operations | J39: Home 2 | K39: TEMU | L39: Fixed | M39: Mizanur Rahman | N39: Asif Iqbal | O39: Ashraful Haq | P39: 20 | Q39: 45256 | R39: 45261 | W39: sungidaalam99@gmail.com | X39: 1317118434 | Y39: 1798174131 | Z39: Md. Shohanur Rahman | AA39: 1798174131 | AB39: Husband | AC39: O+ | AD39: 36404 | AE39: =((TODAY())-AD39)/365 -> 25.460274 | AF39: Islam | AG39: 7354237898 | AH39: N/A | AI39: Graduation | AJ39: N/A | AK39: 2023 | AL39: Green University Of Bangladesh | AM39: Md. Nazrul Alam | AN39: Tazbina Akter | AO39: Road - 14, house- 1, Nikunja - 2, khilkhet, Dhaka | AP39: Road- osman khan , area - Alipur , post code - 7800, thana- kotowali, Dis - Faridpur | AQ39: Khilkhet | AR39: Married | AS39: Md. Shohanur Rahman | AT39: 35638 | AU39: N/A | AV39: N/A | AW39: N/A | AX39: N/A | BA39: Active | BB39: 10800 | BC39: 2700 | BD39: 0 | BE39: Morning | BH39: Done
A40: 171286 | C40: heibulin29op | D40: Afroza Khan | E40: Female | F40: 1110586404 | G40: CSO | H40: Content Moderator | I40: Operations | J40: Home 2 | K40: TEMU | L40: Fixed | M40: Mizanur Rahman | N40: Asif Iqbal | O40: Ashraful Haq | P40: 20 | Q40: 45256 | R40: 45261 | W40: afrozakhan4567@gmail.com | X40: 1993494933 | Z40: Ashraful Islam | AA40: 1400523277 | AB40: Husband | AC40: O+ | AD40: 36402 | AE40: =((TODAY())-AD40)/365 -> 25.465753 | AF40: Islam | AG40: 5114875874 | AH40: N/A | AI40: Master’s | AJ40: N/A | AK40: 2021 | AL40: Govt. Titumir College | AM40: Rawshan khan | AN40: Rozi | AO40: Uttarkhan master para holding no 99/3 | AP40: Uttarkhan master para holding no 99/3 | AQ40: Uttar khan | AR40: Married | AS40: Ashraful Islam | AT40: 34860 | AU40: N/A | AV40: N/A | AW40: N/A | AX40: N/A | BA40: Active | BB40: 10800 | BC40: 2700 | BD40: 0 | BE40: Morning | BH40: Done
...

Sheet Inactive
A1: Employee ID | B1: Process ID | C1: Login ID | D1: Employee Name | E1: Gender | F1: SSC Reg Num. | G1: Designation | H1: Functional Designation/Job Role | I1: Department | J1: Process Segment (LOB) | K1: Process | L1: Employment Type | M1: Sup 1 | N1: Sup 2 | O1: HoD | P1: Training Batch | Q1: DOT | R1: DOJ | S1: Contractual Transfer DOJ | T1: Permanent Transfer DOJ | U1: New Role DOJ | V1: Pool Phone | W1: Email | X1: Contact# | Y1: Alt. Cont# | Z1: Emergency Contact Person | AA1: Emergency Number | AB1: Rel. with Employee | AC1: Blood Group | AD1: DOB | AE1: Age | AF1: Religion | AG1: NID# | AH1: Passport# | AI1: Academic Qualification | AJ1: Education Pursuing | AK1: Pursuing Eduction End Year | AL1: Institution | AM1: Father's Name | AN1: Mother's Name | AO1: Present Address | AP1: Permanent Address | AQ1: Location | AR1: Marital Status | AS1: Spouse Name | AT1: Spouse DOB | AU1: Child-1 Name | AV1: Child-1 DOB | AW1: Child-2 Name | AX1: Child-2 DOB | AY1: Child-3 Name | AZ1: Child-3 DOB | BA1: Status | BB1: Rate 1 | BC1: Rate 2 | BD1: Rate 3 | BE1: Shift | BF1: Previous Employee ID | BG1: Previous Process | BH1: Separation Type | BI1: Inactive Date | BJ1: Reason | BK1: Tenure | BL1: MDB Update | BM1: Official email ID | BN1: HR Comments | BO1: Bkash Number
A2: 171052 | D2: Md.Obit Hassan Orid | E2: Male | F2: 954554 | G2: CSO | H2: Moderator | I2: Operation | J2: Content Moderation and Data Annotation | K2: Temu | L2: Apprentice Fixed | M2: Halima Akter | N2: Asif Iqbal | O2: Abdallah Shaadh Rahman | P2: Temu Batch-3 | Q2: 45033 | R2: 45040 | W2: obitassanorid@gmail.com | X2: 1853024234 | Z2: Suborna | AA2: 1643436022 | AB2: Wife | AC2: A+ | AD2: 35557 | AE2: 26.958904 | AF2: Islam | AG2: 4208022964 | AH2: N/A | AI2: Undergraduate | AJ2: Hon's (3rd year) | AK2: 2025 | AL2: Mirpur college | AM2: Abul hossain | AN2: Aiju begum | AO2: H-19,R-24,Ave-5,Block-C,Section-11,Mirpur Dhaka-1216 | AP2: H-19,R-24,Ave-5,Block-C,Section-11,Mirpur Dhaka-1216 | AQ2: H-19,R-24,Ave-5,Block-C,Section-11,Mirpur Dhaka-1216 | AR2: Married | BA2: Agent | BB2: 12000 | BC2: 3000 | BD2: 0 | BE2: Morning | BF2: 160764 | BG2: Netstar | BH2: Separated | BI2: =VLOOKUP(A2,'ID Block'!A:L,12,0) -> 45066 | BJ2: =VLOOKUP(A2,'ID Block'!A:M,13,0) -> Unauthorized absent | BK2: =BI2-R2 -> 26 | BL2: Done
A3: 171034 | D3: Dipankar Saha Dipto | E3: Male | F3: - | G3: CSO | H3: Moderator | I3: Operation | J3: - | K3: Temu | L3: Apprentice Fixed | M3: OJT | N3: Asif Iqbal | O3: Abdallah Shaadh Rahman | P3: Temu Batch-3 | Q3: 45033 | R3: 45040 | W3: - | X3: - | Y3: - | Z3: - | AA3: - | AB3: - | AC3: - | AD3: - | AE3: #VALUE! | AF3: - | AG3: - | AH3: N/A | AI3: - | AJ3: - | AK3: - | AL3: - | AM3: - | AN3: - | AO3: - | AP3: - | AQ3: - | AR3: - | BA3: Agent | BB3: 10800 | BC3: 2700 | BD3: 0 | BE3: Morning | BF3: 161739 | BG3: Netstar | BH3: Separated | BI3: =VLOOKUP(A3,'ID Block'!A:L,12,0) -> 45047 | BJ3: =VLOOKUP(A3,'ID Block'!A:M,13,0) -> Unauthorized absent | BK3: =BI3-R3 -> 7 | BL3: Done
A4: 171041 | D4: Fakrul Hasan Asif | E4: Male | F4: 1211884560 | G4: CSO | H4: Moderator | I4: Operation | J4: Content Moderation and Data Annotation | K4: Temu | L4: Apprentice Fixed | M4: Md. Fahim Hossain Hemal | N4: Asif Iqbal | O4: Abdallah Shaadh Rahman | P4: Temu Batch-3 | Q4: 45034 | R4: 45040 | W4: fukrulasif3891@gmail.com | X4: 1905119370 | Z4: Payer Ahmed | AA4: 1835343831 | AB4: Father | AC4: AB+ | AD4: 36128 | AE4: 25.394521 | AF4: Islam | AG4: 6454652337 | AH4: N/A | AI4: Undergraduate | AJ4: Computer Science and Engineering | AK4: 2024 | AL4: Bangladesh university of business and technology | AM4: Payer Ahmed | AN4: Fatema Begum | AO4: 170/2 pathowary house,Kuril chowrasta,kuril. | AP4: Ali Ajghar Patowary house,middle rampur,Feni sadar,Feni. | AQ4: 170/2 pathowary house,Kuril chowrasta,kuril. | AR4: Unmarried | BA4: Agent | BB4: 12000 | BC4: 3000 | BD4: 0 | BE4: Morning | BF4: 161296 | BG4: Netstar | BH4: Resignation | BI4: =VLOOKUP(A4,'ID Block'!A:L,12,0) -> 45078 | BJ4: =VLOOKUP(A4,'ID Block'!A:M,13,0) -> New Opportunity | BK4: =BI4-R4 -> 38 | BL4: Done
A5: 171065 | D5: Abdul Aual Arafat | E5: Male | G5: CSO | H5: Moderator | I5: Operation | K5: Temu | L5: Apprentice Fixed | M5: Abdul Moontakim Alif | N5: Asif Iqbal | O5: Abdallah Shaadh Rahman | P5: Temu Batch-7 | Q5: 45063 | R5: 45072 | X5: 1750770158 | AE5: 124.37534 | AF5: Islam | AH5: N/A | BA5: Agent | BB5: 12000 | BC5: 3000 | BD5: 0 | BE5: Morning | BF5: 161383 | BG5: Netstar | BH5: Resignation | BI5: =VLOOKUP(A5,'ID Block'!A:L,12,0) -> 45084 | BJ5: =VLOOKUP(A5,'ID Block'!A:M,13,0) -> Personal Issue | BK5: =BI5-R5 -> 12 | BL5: Done | BN5: Japanese language learning
A6: 171032 | D6: Mst Rammi Akter | E6: Female | F6: 639923 | G6: CSO | H6: Moderator | I6: Operation | J6: Content Moderation and Data Annotation | K6: Temu | L6: Apprentice Fixed | M6: Halima Akter | N6: Asif Iqbal | O6: Abdallah Shaadh Rahman | P6: Temu Batch-3 | Q6: 45033 | R6: 45040 | W6: rammiakter.bd@gmail.com | X6: 1785992222 | Z6: MD. Abdur Razzak | AA6: 1736704414 | AB6: Father | AC6: O+ | AD6: 34589 | AE6: 29.610959 | AF6: Islam | AG6: 8228652460 | AH6: B00338658 | AI6: Graduate | AJ6: N/A | AK6: N/A | AL6: National University | AM6: MD. Abdur Razzak | AN6: Mst. Nazma Begum | AO6: Uttara | AP6: Ullipur,Sherpur,Bogura | AQ6: Uttara | AR6: Unmarried | BA6: Agent | BB6: 10800 | BC6: 2700 | BD6: 0 | BE6: Morning | BF6: 161411 | BG6: Netstar | BH6: Resignation | BI6: =VLOOKUP(A6,'ID Block'!A:L,12,0) -> 45083 | BJ6: =VLOOKUP(A6,'ID Block'!A:M,13,0) -> New Opportunity | BK6: =BI6-R6 -> 43 | BL6: Done | BN6: New job opportunity
A7: 171047 | D7: Riad Abdullah | E7: Male | F7: 723061 | G7: CSO | H7: Moderator | I7: Operation | J7: Content Moderation and Data Annotation | K7: Temu | L7: Apprentice Fixed | M7: Halima Akter | N7: Asif Iqbal | O7: Abdallah Shaadh Rahman | P7: Temu Batch-3 | Q7: 45033 | R7: 45040 | W7: Abdullahriad003@gmail.com | X7: 1743674224 | Z7: Rahat Abdullah | AA7: 1312266277 | AB7: Brother | AC7: AB+ | AD7: 35188 | AE7: 27.969863 | AF7: Islam | AG7: 19966125205000104 | AH7: BX0139499 | AI7: Undergraduate | AJ7: BSC in CSE 3rd year | AK7: 2024 | AL7: Sonargaon University, Dhaka | AM7: Abdullahel Mahmud | AN7: Mahbuba Akhter | AO7: Tolarbagh, Mirpur-1, Dhaka | AP7: 28, Zilla school road, Mymensingh | AQ7: Mymensingh | AR7: Unmarried | BA7: Agent | BB7: 12000 | BC7: 3000 | BD7: 0 | BE7: Morning | BF7: 161039 | BG7: Netstar | BH7: Resignation | BI7: =VLOOKUP(A7,'ID Block'!A:L,12,0) -> 45082 | BJ7: =VLOOKUP(A7,'ID Block'!A:M,13,0) -> Personal Issue | BK7: =BI7-R7 -> 42 | BL7: Done | BN7: Personal issues (Resignation letter received on June 11, 2023
A8: 171054 | D8: Tajim Nur | E8: Female | F8: 1510793691 | G8: CSO | H8: Moderator | I8: Operation | J8: English Customer Service Audio Transcription | K8: Temu | L8: Apprentice Fixed | M8: Abdul Moontakim Alif | N8: Asif Iqbal | O8: Abdallah Shaadh Rahman | P8: Temu Batch-3 | Q8: 45033 | R8: 45040 | W8: tanjimnishu747@gmail.com | X8: 1813164079 | Z8: Taslima akter | AA8: 1782179040 | AB8: Mother | AC8: O+ | AD8: 37637 | AE8: 21.260274 | AF8: Islam | AG8: 20032692526350565 | AH8: A01695198 | AI8: Undergraduate | AJ8: Honour's Running | AK8: 2024 | AL8: Southern college | AM8: Nurun nubi | AN8: Taslima Akter | AO8: Kawla,ambagan p2/3 stuff quater | AP8: G.p.go 31/B middle badda Monoyara villa | AQ8: Badda | AR8: Unmarried | BA8: Agent | BB8: 10800 | BC8: 2700 | BD8: 0 | BE8: Morning | BF8: 160891 | BG8: Netstar | BH8: Resignation | BI8: =VLOOKUP(A8,'ID Block'!A:L,12,0) -> 45093 | BJ8: =VLOOKUP(A8,'ID Block'!A:M,13,0) -> Study purpose | BK8: =BI8-R8 -> 53 | BL8: Done | BN8: Study purpose
A9: 171013 | D9: Md Touhiduzzaman Bhuiyan | E9: Male | F9: 658732 | G9: CSO | H9: Moderator | I9: Operation | J9: Product's Review for Risk Control | K9: Temu | L9: Apprentice Fixed | M9: Md. Fahim Hossain Hemal | N9: Asif Iqbal | O9: Abdallah Shaadh Rahman | P9: Temu Batch-1 | Q9: 45023 | R9: 45032 | W9: Touhiduzamanbhuiyan17@gmail.com | X9: 1865653928 | Z9: Ummey Habiba | AA9: 1625267207 | AB9: Wife | AC9: B+ | AD9: 33832 | AE9: 31.684932 | AF9: Islam | AG9: 3297143749 | AH9: N/A | AI9: Undergraduate | AJ9: BBA | AK9: 2023 | AL9: Southeast university | AM9: Md Abdur Razzaque Bhuiyan | AN9: Nurun nahar | AO9: House:12/4, road: 01,kallyanpur,Dhaka | AP9: House:12/4, road: 01,kallyanpur,Dhaka | AQ9: Mirpur, Dhaka | AR9: Married | BA9: Agent | BB9: 10800 | BC9: 2700 | BD9: 0 | BE9: Morning | BF9: 160336 | BG9: Netstar | BH9: Resignation | BI9: =VLOOKUP(A9,'ID Block'!A:L,12,0) -> 45094 | BJ9: =VLOOKUP(A9,'ID Block'!A:M,13,0) -> New Opportunity | BK9: =BI9-R9 -> 62 | BL9: Done | BN9: New job opportunity
A10: 171064 | D10: Khadiza Khanom Boby | E10: Female | F10: 1110366718 | G10: CSO | H10: Moderator | I10: Operation | J10: Content Moderation and Data Annotation | K10: TEMU | L10: Apprentice Fixed | M10: Halima Akter | N10: Asif Iqbal | O10: Abdallah Shaadh Rahman | P10: Temu Batch-7 | Q10: 45063 | R10: 45072 | W10: khadizakhanom245@gmail.com | X10: 1959026697 | Y10: N/A | Z10: MD.Bachu Mia | AA10: +8801731184594 | AB10: Father | AC10: B+ | AD10: 35456 | AE10: 27.235616 | AF10: Islam | AG10: 19972650898000000 | AH10: N/A | AI10: B.B.A | AJ10: N/A | AK10: N/A | AL10: Eden Mohila College | AM10: MD.Bachu Mia | AN10: Rina Akter | AO10: Brahmanbaria,District:Bacharampur,Village:achadnagar | AP10: Matikata Bazar,Dhaka Cantonment | AQ10: Brahmanbaria,District:Bacharampur,Village:achadnagar | AR10: Unmarried | BA10: Agent | BB10: 10800 | BC10: 2700 | BD10: 0 | BE10: Morning | BF10: 161098 | BG10: Netstar | BH10: Resignation | BI10: =VLOOKUP(A10,'ID Block'!A:L,12,0) -> 45097 | BJ10: =VLOOKUP(A10,'ID Block'!A:M,13,0) -> New Opportunity | BK10: =BI10-R10 -> 25 | BL10: Done | BM10: khadiza.boby@genex.com.bd | BN10: New job opportunity
A11: 171085 | C11: Genex027 | D11: Fazla Rabbi | E11: Male | F11: 1010734088 | G11: CSO | H11: Moderator | I11: Operation | J11: BG Platform Governance Requirements | K11: TEMU | L11: Apprentice Fixed | M11: Abdul Moontakim Alif | N11: Asif Iqbal | O11: Abdallah Shaadh Rahman | P11: Temu Batch-8 | Q11: 45077 | R11: 45090 | W11: rabbimahmud276@gmail.com | X11: 1716403297 | Y11: 1950406416 | Z11: Ehsanul kabir Avi | AA11: 1938848797 | AB11: Brother | AC11: B+ | AD11: 35445 | AE11: 27.265753 | AF11: Islam | AG11: 1.9978218e+16 | AH11: N/A | AI11: B.B.A | AJ11: MBA | AK11: 45137 | AL11: Rajbari Govt College | AM11: Sharafat karim | AN11: Nilufa Yesmin | AO11: House no-41/42,Road-2,Block -G(A),Section -6,Mirpur 10,Dhaka -1216 | AP11: Vill:Laxminarayanpur, Post:Banibho,Thana : Rajbari sadar ,Dist:Rajbari | AQ11: House no-41/42,Road-2,Block -G(A),Section -6,Mirpur 10,Dhaka -1216 | AR11: Unmarried | BA11: Agent | BB11: 10800 | BC11: 2700 | BD11: 2500 | BE11: Night | BH11: Separated | BI11: =VLOOKUP(A11,'ID Block'!A:L,12,0) -> 45091 | BJ11: =VLOOKUP(A11,'ID Block'!A:M,13,0) -> Unauthorized absent | BK11: =BI11-R11 -> 1 | BL11: Done
A12: 171007 | D12: Md. Sakil Ahamed | E12: Male | F12: 1115251923 | G12: CSO | H12: Moderator | I12: Operation | J12: Product's Review for Risk Control | K12: TEMU | L12: Apprentice Fixed | M12: Md. Fahim Hossain Hemal | N12: Asif Iqbal | O12: Abdallah Shaadh Rahman | P12: Temu Batch-1 | Q12: 45023 | R12: 45032 | W12: sakiltanzim@gmail.com | X12: 1630336594 | Z12: Md.Shajahan mia | AA12: 1718992506 | AB12: Father | AC12: A+ | AD12: 36161 | AE12: 25.30411 | AF12: Islam | AG12: 2404194751 | AH12: A05117759 | AI12: Graduate | AJ12: N/A | AK12: N/A | AL12: Govt. Brojumohon College | AM12: Md. Shajahan mia | AN12: Mukul begum | AO12: House no 13, road no 7,Nikunja 2,Khilkhet,Dhaka | AP12: Vill: meghia, post : chadpasha, Union:Madhapasha,dist: Barishal | AQ12: Nikunja 2,khilkhet | AR12: Unmarried | BA12: Agent | BB12: 10800 | BC12: 2700 | BD12: 0 | BE12: Morning | BF12: 161641 | BG12: Netstar | BH12: Resignation | BI12: =VLOOKUP(A12,'ID Block'!A:L,12,0) -> 45103 | BJ12: =VLOOKUP(A12,'ID Block'!A:M,13,0) -> Study purpose | BK12: =BI12-R12 -> 71 | BL12: Done | BM12: sakil.ahmed@genex.com.bd | BN12: Study purpose
A13: 171016 | D13: Md. Rabby | E13: Male | F13: 1314425385 | G13: CSO | H13: Moderator | I13: Operation | J13: Content Moderation and Data Annotation | K13: TEMU | L13: Apprentice Fixed | M13: Abdul Moontakim Alif | N13: Asif Iqbal | O13: Abdallah Shaadh Rahman | P13: Temu Batch-2 | Q13: 45029 | R13: 45042 | W13: mrabby1112@gmail.com | X13: 1785816292 | Z13: Rina Begum | AA13: 1879935183 | AB13: Mother | AC13: O+ | AD13: 36216 | AE13: 25.153425 | AF13: Islam | AG13: 19991591610136439 | AH13: N/A | AI13: Undergraduate | AJ13: BBA Final | AK13: 2024 | AL13: Uttar Kattali Nurul Haque Chowdhury University and College | AM13: Jahirul Islam | AN13: Rina Begum | AO13: Cherag Ali, Tongi | AP13: Barkhappan, Netrokona | AQ13: Tongi | AR13: Unmarried | BA13: Agent | BB13: 10800 | BC13: 2700 | BD13: 0 | BE13: Morning | BF13: 161581 | BG13: Netstar | BH13: Separated | BI13: =VLOOKUP(A13,'ID Block'!A:L,12,0) -> 45103 | BJ13: =VLOOKUP(A13,'ID Block'!A:M,13,0) -> Unethical Activities | BK13: =BI13-R13 -> 61 | BL13: Done | BM13: md.rabby@genex.com.bd | BN13: Forcefully resigned due to using abusing word toward a employee
A14: 171098 | D14: Dewa Raisul Islam Rohit | E14: Male | G14: CSO | H14: Moderator | I14: Operation | J14: Identification of the same product | K14: TEMU | L14: Apprentice Fixed | M14: Halima Akter | N14: Asif Iqbal | O14: Abdallah Shaadh Rahman | P14: Temu Batch-10 | Q14: 45110 | R14: 45113 | X14: 1302848048 | Z14: Zahidul Islam | AA14: 1932901290 | AB14: Brother in law | AC14: A+ | AD14: 36543 | AE14: 24.257534 | AF14: Islam | AG14: 9175257196 | AH14: N/A | AI14: Graduate | AJ14: N/A | AK14: N/A | AL14: IUBAT | AM14: Deoan Monzur Rahman | AN14: Deoan Salma Monju | AO14: R-11, H-35, Block D, Pallabi, Mirpur 12, Dhaka 1216 | AP14: Vill: Tewria, P.O: Choktail, P.S: Delduar, D: Tangail. | AQ14: Mirpur 12 | AR14: Unmarried | BA14: Agent | BB14: 10800 | BC14: 2700 | BD14: 0 | BE14: Morning | BF14: - | BG14: - | BH14: Resignation | BI14: =VLOOKUP(A14,'ID Block'!A:L,12,0) -> 45117 | BJ14: =VLOOKUP(A14,'ID Block'!A:M,13,0) -> New Opportunity | BK14: =BI14-R14 -> 4 | BL14: Done | BN14: New job opportunity
A15: 171067 | C15: Genex006 | D15: Md Shoyeb Rana | E15: Male | F15: 770102 | G15: CSO | H15: Moderator | I15: Operation | J15: BG Platform Governance Requirements | K15: TEMU | L15: Apprentice Fixed | M15: Abdul Moontakim Alif | N15: Asif Iqbal | O15: Abdallah Shaadh Rahman | P15: Temu Batch-8 | Q15: 45077 | R15: 45090 | W15: shoyebrana94@gmail.com | X15: 1674672004 | Y15: 1712922170 | Z15: Md Anar Mia | AA15: 1760207797 | AB15: Father | AC15: B+ | AD15: 34532 | AE15: 29.767123 | AF15: Islam | AG15: 8210764265A | AH15: A03557397 | AI15: B.B.S | AJ15: N/A | AK15: N/A | AL15: Govt.Gurudoyal College, Kishoreganj | AM15: Md Anar Mia | AN15: Mst Sheuli Begum | AO15: Area : Nikunjo 2, Road No 09,House : 25 , Thana : Khikhet , Dist : Dhaka | AP15: Vill : Sorarchor, Thana : Bajitpur,Dist : Kishorganj | AQ15: Nikunjo 2, Khikhet | AR15: Unmarried | BA15: Agent | BB15: 10800 | BC15: 2700 | BD15: 2500 | BE15: Night | BF15: - | BG15: - | BH15: Resignation | BI15: =VLOOKUP(A15,'ID Block'!A:L,12,0) -> 45115 | BJ15: =VLOOKUP(A15,'ID Block'!A:M,13,0) -> Health Issue | BK15: =BI15-R15 -> 25 | BL15: Done | BN15: Health Issue
A16: 171089 | D16: Sakib R Rahman | E16: Male | F16: 1215381237 | G16: CSO | H16: Moderator | I16: Operation | J16: Identification of the same product | K16: TEMU | L16: Apprentice Fixed | M16: Halima Akter | N16: Asif Iqbal | O16: Abdallah Shaadh Rahman | P16: Temu Batch-10 | Q16: 45110 | R16: 45113 | W16: sakibrrahman@gmail.com | X16: 1737211564 | Y16: 1303675113 | Z16: MD. Al Mamun | AA16: 1785571017 | AB16: Friend | AC16: O+ | AD16: 36272 | AE16: 24 | AF16: Islam | AG16: 8254856316 | AH16: N/A | AI16: HSC | AJ16: B.A. | AK16: 2024 | AL16: Patuakhali Govt College , Patuakhali | AM16: MD. Mizanur Rahman | AN16: Sobita Akter | AO16: House- 1/3/A, North Pirerbag, 60 Feet, Mirpur- 02, Dhaka. | AP16: Area- Fire Service Road, Patuakhali Sadar , Patuakhali | AQ16: Mirpur-02 | AR16: Unmarried | BA16: Agent | BB16: 10800 | BC16: 2700 | BD16: 0 | BE16: Morning | BF16: - | BG16: - | BH16: Separated | BI16: =VLOOKUP(A16,'ID Block'!A:L,12,0) -> 45117 | BJ16: =VLOOKUP(A16,'ID Block'!A:M,13,0) -> Unauthorized absent | BK16: =BI16-R16 -> 4 | BL16: Done
A17: 171072 | C17: Genex012 | D17: Md. Ashir Ahmed | E17: Male | F17: 1012663014 | G17: CSO | H17: Content Moderator | I17: Operation | J17: BG Platform Governance Requirements | K17: TEMU | L17: Apprentice Fixed | M17: Abdul Moontakim Alif | N17: Asif Iqbal | O17: Abdallah Shaadh Rahman | P17: Temu Batch-8 | Q17: 45077 | R17: 45090 | W17: ashirislam44@gmail.com | X17: 1773971286 | Y17: 1812365339 | Z17: Al Mostakima Rahman | AA17: 1317526252 | AB17: Wife | AC17: B+ | AD17: 35685 | AE17: 26.608219 | AF17: Islam | AG17: 6003067334 | AH17: A00075275 | AI17: B.B.A | AJ17: N/A | AK17: N/A | AL17: Pundra University Of Science And Technology | AM17: Md Abdul Hanna | AN17: Mst Afruja Begum | AO17: Area : 426/3 Shamim Soroni, West Shawrapara,Thana : Mirpur, Dist : Dhaka | AP17: Vill : Natai Purbo Para, Thana : Bogura Sadar Dist : Bogura | AQ17: Shamim Soroni, West Shawrapara, | AR17: Married | AS17: Al Mostakima Rahman | AT17: 36413 | BA17: Agent | BB17: 10800 | BC17: 2700 | BD17: 2500 | BE17: Night | BF17: - | BG17: - | BH17: Resignation | BI17: =VLOOKUP(A17,'ID Block'!A:L,12,0) -> 45122 | BJ17: =VLOOKUP(A17,'ID Block'!A:M,13,0) -> New Opportunity | BK17: =BI17-R17 -> 32 | BL17: Done | BN17: New job opportunity
A18: 171040 | C18: mmaigenex009 | D18: Yeasin Arafat | E18: Male | F18: 1410927916 | G18: CSO | H18: Content Moderator | I18: Operation | J18: Content Moderation and Data Annotation | K18: TEMU | L18: Apprentice Fixed | M18: Md. Fahim Hossain Hemal | N18: Asif Iqbal | O18: Abdallah Shaadh Rahman | P18: Temu Batch-3 | Q18: 45033 | R18: 45040 | W18: ryrony404@gmail.com | X18: 1936495092 | Z18: Salma Islam | AA18: 1821736384 | AB18: Mother | AC18: O+ | AD18: 36840 | AE18: 23.443836 | AF18: Islam | AG18: 8263648076 | AH18: N/A | AI18: H.S.C | AJ18: B.B.A Running | AK18: 2025 | AL18: ISTT | AM18: Nazrul Islam | AN18: Salma Islam | AO18: Area : Ananda road,mirpur-14,Thana : Kafrul ,Dist : Dhaka | AP18: Area : Gujadia,Thana : karimganj,Dist : kishorgonj | AQ18: Mirpur-14, Kafrul | AR18: Unmarried | BA18: Agent | BB18: 12000 | BC18: 3000 | BD18: 0 | BE18: Morning | BF18: 161273 | BG18: Netstar | BH18: Resignation | BI18: =VLOOKUP(A18,'ID Block'!A:L,12,0) -> 45121 | BJ18: =VLOOKUP(A18,'ID Block'!A:M,13,0) -> Personal Issue | BK18: =BI18-R18 -> 81 | BL18: Done | BM18: yeasin.arafat@genex.com.bd | BN18: Personal Issue (Family issues)
A19: 171110 | D19: Abu Huraira Shohan | E19: Male | F19: 396303 | G19: CSO | H19: Content Moderator | I19: Operation | J19: Sports & shoes & bags & sepcial women clothing | K19: TEMU | L19: Apprentice Fixed | M19: Halima Akter | N19: Asif Iqbal | O19: Abdallah Shaadh Rahman | P19: Temu Batch-11 | Q19: 45116 | R19: 45127 | W19: huraira.shohan@gmail.com | X19: 1675488690 | Y19: 1534672816 | Z19: Rezuana Binte Helal | AA19: 1749106843 | AB19: Wife | AC19: O+ | AD19: 33793 | AE19: 31.791781 | AF19: Islam | AG19: 7304428167 | AH19: N/A | AI19: B.S.C | AJ19: N/A | AK19: N/A | AL19: American International University Bangladesh | AM19: Late MD. Abdul Khaleq | AN19: Kaniz Fatima Shimo | AO19: Area: House No- 399, Area- Jamtola, Kawlar, Thana: dakkhinkhan Dist :Dhaka | AP19: Area :House- 234, Area- Dhokkhingaon,Thana: Basabo, Dist: Dhaka-1214 | AQ19: Kawlar | AR19: Married | BA19: Agent | BB19: 10800 | BC19: 2700 | BD19: 0 | BE19: Morning | BF19: - | BG19: - | BH19: Separated | BI19: =VLOOKUP(A19,'ID Block'!A:L,12,0) -> 45132 | BJ19: =VLOOKUP(A19,'ID Block'!A:M,13,0) -> Unauthorized absent | BK19: =BI19-R19 -> 5 | BL19: Done
A20: 171012 | C20: Mahdir Hossain | D20: Mahdir Hossain | E20: Male | F20: 1210878572 | G20: CSO | H20: Content Moderator | I20: Operation | J20: English Customer Service Audio Transcription | K20: TEMU | L20: Apprentice Fixed | M20: MD. Fahim Hossain Hemal | N20: Asif Iqbal | O20: Abdallah Shaadh Rahman | P20: Temu Batch-1 | Q20: 45023 | R20: 45032 | W20: tekinoff28@gmail.com | X20: 1613446021 | Z20: Ferdousi Akhter Konika | AA20: 1910816500 | AB20: Mother | AC20: A+ | AD20: 35974 | AE20: 25.816438 | AF20: Islam | AG20: 19993326611056598 | AH20: N/A | AI20: H.S.C | AJ20: B.B.A Running | AK20: 2023 | AL20: Bhawal badre alam govt. college | AM20: Hossain Ahmed Khan | AN20: Ferdousi Akhter | AO20: House : Ferdousi kunja, 124 Area : Dattapara banamala road, Thana : Tongi, Dist : Gazipur | AP20: Vill : Autshahi , P:O: Autshahi ,Thana : Tongi Bari District: Munshiganj | AQ20: Dattapara banamala road, Tongi | AR20: Unmarried | BA20: Agent | BB20: 10800 | BC20: 2700 | BD20: 0 | BE20: Morning | BF20: 160019 | BG20: Netstar | BH20: Resignation | BI20: =VLOOKUP(A20,'ID Block'!A:L,12,0) -> 45128 | BJ20: =VLOOKUP(A20,'ID Block'!A:M,13,0) -> New Opportunity | BK20: =BI20-R20 -> 96 | BL20: Done | BM20: mahdir.hossain@genex.com.bd | BN20: New job opportunity
A21: 171037 | C21: mmaigenex006 | D21: Abdullah Khan | E21: Male | F21: 1410927742 | G21: CSO | H21: Content Moderator | I21: Operation | J21: Content Moderation and Data Annotation | K21: TEMU | L21: Apprentice Fixed | M21: Md. Fahim Hossain Hemal | N21: Asif Iqbal | O21: Abdallah Shaadh Rahman | P21: Temu Batch-3 | Q21: 45033 | R21: 45040 | W21: abdullahkhan2987966@gmail.com | X21: 1995536257 | Z21: Sumaiya khan | AA21: 1930679007 | AB21: Sister | AC21: A+ | AD21: 36448 | AE21: 24.517808 | AF21: Islam | AG21: 9174068990 | AH21: N/A | AI21: H.S.C | AJ21: B.B.A Running | AK21: 2025 | AL21: Institute of science & technology (ISTT) | AM21: Abdur Rahman | AN21: Sufia Rahman | AO21: Area : Mirpur 13, Ayna moshjid , Thana: Kafrul , Dist : Dhaka | AP21: Area : Mirpur 13, Ayna moshjid , Thana: Kafrul , Dist : Dhaka | AQ21: Mirpur 13, Kafrul | AR21: Unmarried | BA21: Agent | BB21: 10800 | BC21: 2700 | BD21: 0 | BE21: Morning | BF21: 161251 | BG21: Netstar | BH21: Separated | BI21: =VLOOKUP(A21,'ID Block'!A:L,12,0) -> 45134 | BJ21: =VLOOKUP(A21,'ID Block'!A:M,13,0) -> Unauthorized absent (ZTP) | BK21: =BI21-R21 -> 94 | BL21: Done | BM21: abdullah.khan@genex.com.bd | BN21: Unreachable (He had ZTP issue)
